# üîç Security Scan Report

**Scan Date:** 2025-05-25 06:45:57 UTC
**Repository:** yantology/generatecv
**Branch:** main
**Commit:** 3e720518e9a65f0902a7c40ee87a5be8d9e20869

## üö® Dependency Vulnerabilities

### pip-audit scan:
```
‚ö†Ô∏è **pip-audit scan failed or encountered errors**
Traceback (most recent call last):
  File "/home/runner/work/generatecv/generatecv/.venv/lib/python3.13/site-packages/pip_audit/_service/pypi.py", line 63, in query
    response.raise_for_status()
    ~~~~~~~~~~~~~~~~~~~~~~~~~^^
  File "/home/runner/work/generatecv/generatecv/.venv/lib/python3.13/site-packages/requests/models.py", line 1024, in raise_for_status
    raise HTTPError(http_error_msg, response=self)
requests.exceptions.HTTPError: 406 Client Error: go-http-client redirect for url: https://pypi.org/pypi/annotated-types/0.7.0/json

The above exception was the direct cause of the following exception:

Traceback (most recent call last):
  File "/home/runner/work/generatecv/generatecv/.venv/bin/pip-audit", line 10, in <module>
    sys.exit(audit())
             ~~~~~^^
  File "/home/runner/work/generatecv/generatecv/.venv/lib/python3.13/site-packages/pip_audit/_cli.py", line 538, in audit
    for spec, vulns in auditor.audit(source):
                       ~~~~~~~~~~~~~^^^^^^^^
  File "/home/runner/work/generatecv/generatecv/.venv/lib/python3.13/site-packages/pip_audit/_audit.py", line 68, in audit
    for dep, vulns in self._service.query_all(specs):
                      ~~~~~~~~~~~~~~~~~~~~~~~^^^^^^^
```

### safety scan (backup):
```
‚ö†Ô∏è **Safety scan completed with warnings or deprecated**


[33m[1m+===========================================================================================================================================================================================+[0m


[31m[1mDEPRECATED: [0m[33m[1mthis command (`check`) has been DEPRECATED, and will be unsupported beyond 01 June 2024.[0m


[32mWe highly encourage switching to the new [0m[32m[1m`scan`[0m[32m command which is easier to use, more powerful, and can be set up to mimic the deprecated command if required.[0m


[33m[1m+===========================================================================================================================================================================================+[0m


[31mUnhandled exception happened: post_dump() got an unexpected keyword argument 'pass_many'[0m
```

## üîç Code Security Analysis

‚úÖ **No code security issues found!**

## üìä Scan Summary

- **Dependencies scanned:** 109
- **Python files scanned:** 9
- **Vulnerabilities found:** No
- **Code issues found:** No

---
*This report was generated automatically by the security scanning workflow.*
